Workbook

Sheet Leia-me
A1: Varredura de imóveis em leilão — 08/10/2026 07h
A3: COMO USAR
A4: 1. Abra a aba Premissas. Só as células amarelas se editam.
A5: 2. Mude uma premissa (condomínio atrasado, desocupação, reforma) e todas as abas se refazem.
A6: 3. Na aba Viabilidade, a coluna F (Lance) também é amarela: simule o lance que quiser.
A7: 4. A coluna Veredicto diz se o lote passa no mandato do perfil-investidor.md.
A9: O QUE TEM NESTE ARQUIVO
A10: Aprovados na triagem — lotes dentro da praça-alvo, com a viabilidade calculada por fórmula.
A11: Todos os lotes — tudo que a varredura coletou, inclusive o que foi descartado e por quê.
A12: Comparáveis — os anúncios de mercado que formam o VVR.
A13: Saíram da lista — lotes que deixaram o portal, para calibrar lance futuro.
A14: Premissas — os inputs.
... A26: matrícula atualizada, débito de condomínio por escrito, e advogado.

Sheet Premissas
A1: Premissas da varredura
A2: Só se edita esta aba. As células amarelas alimentam por fórmula todas as contas das outras abas — mude uma e a margem e o lance máximo se refazem sozinhos.
A4: Custos sobre o lance
A5: Comissão do leiloeiro | B5: 0.05 | C5: Edital do lote. 5% é o padrão da Caixa, mas confira.
A6: ITBI | B6: 0.03 | C6: Palhoça: faixa de 2% a 3%. Confirmar na Prefeitura.
A7: Registro e escritura | B7: 0.012 | C7: Tabela de emolumentos de SC.
A8: Dívidas e custos fixos
A9: IPTU atrasado | B9: 3000 | C9: Faixa R$ 1 a 5 mil. Em hasta pública sub-roga no preço (Tema 1.134 STJ).
A10: Condomínio atrasado | B10: 12000 | C10: Faixa R$ 0 a 20 mil. É o item que mais move a margem — peça por escrito à administradora.
A11: Contas de consumo | B11: 800 | C11: Água e luz em atraso.
A12: Desocupação | B12: 15000 | C12: Acordo: R$ 5 a 25 mil. Litigiosa: R$ 10 a 40 mil e 12 a 36 meses.
A13: Reforma por m² | B13: 550 | C13: Leve: R$ 400 a 700/m². Pesada: R$ 900 a 1.800/m². Sem vistoria é estimativa.
A14: Carrego mensal | B14: 559 | C14: Condomínio mediano do bairro (R$ 399, n=20) + IPTU + consumo.
A15: Meses do ciclo | B15: 12 | C15: Arrematação até a venda. O perfil aceita 6 a 12 meses.
A16: Saída e mandato
A17: Custo de venda (corretagem) | B17: 0.06 | C17: Definido no perfil-investidor.md.
A18: Fator de deságio do VVR | B18: 0.88 | C18: Venda em 90 dias. Definido no perfil-investidor.md.
A19: Margem líquida mínima | B19: 0.25 | C19: Abaixo disso o perfil manda descartar.
A20: Mercado e caixa
A21: R$/m² de mercado | B21: 5913 | C21: Mediana de 13 anúncios de 2 dorm. entre 42 e 49 m² em Bela Vista, 23/09/2026.
A22: Capital disponível | B22: 100000 | C22: Perfil: R$ 50.000 a R$ 100.000. Aqui no topo da faixa.
A23: % do lance pago à vista | B23: 1 | C23: 100% = sem financiamento. Nenhum lote de Palhoça aceita financiamento.
A25: Legenda
A26: azul sobre amarelo = você edita
A27: preto = fórmula, não mexa
A28: verde = vem de outra aba

Sheet Aprovados na triagem
A1: Aprovados na triagem
A2: Lotes dentro da praça-alvo do perfil. Amarelo = você edita. Tudo o mais é fórmula que lê a aba Premissas.
A4: Nº do imóvel | B4: Bairro | C4: Endereço | D4: Área priv. (m²) | E4: Avaliação Caixa | F4: Lance (piso) | G4: VVR | H4: Comissão | I4: ITBI | J4: Registro | K4: Dívidas | L4: Desocupação | M4: Reforma | N4: Carrego | O4: CTA | P4: Receita líq. de venda | Q4: Lucro | R4: Margem | S4: Lance máx. p/ margem | T4: Lance máx. p/ caixa | U4: Falta de caixa | V4: Veredicto | W4: Situação | X4: Modalidade | Y4: Matrícula | Z4: 1º leilão | AA4: 2º leilão | AB4: Edital | AC4: FGTS | AD4: Financia? | AE4: Link
A5: 878770561220-5 | B5: BELA VISTA | C5: RUA SEBASTIAO ALZEMIRO DOS SANTOS,N. 387 APTO. 104 BL 10 VG182, BELA VISTA - CEP: 88137-640, PALHOCA - SANTA CATARINA | D5: 43.8 | E5: 252000 | F5: 151200 | G5: =D5*Premissas!$B$21*Premissas!$B$18 | H5: =F5*Premissas!$B$5 | I5: =F5*Premissas!$B$6 | J5: =F5*Premissas!$B$7 | K5: =Premissas!$B$9+Premissas!$B$10+Premissas!$B$11 | L5: =Premissas!$B$12 | M5: =D5*Premissas!$B$13 | N5: =Premissas!$B$14*Premissas!$B$15 | O5: =F5+H5+I5+J5+K5+L5+M5+N5 | P5: =G5*(1-Premissas!$B$17) | Q5: =P5-O5 | R5: =IFERROR(Q5/O5,0) | S5: =(P5/(1+Premissas!$B$19)-(K5+L5+M5+N5))/(1+(Premissas!$B$5+Premissas!$B$6+Premissas!$B$7)) | T5: =IFERROR((Premissas!$B$22-(K5+L5+M5+N5))/(Premissas!$B$23+(Premissas!$B$5+Premissas!$B$6+Premissas!$B$7)),0) | U5: =Premissas!$B$22-O5 | V5: =IF(U5<0,"Fora de alcance: falta caixa",IF(R5<Premissas!$B$19,"Reprova: margem abaixo do mínimo","Persegue")) | W5: Ocupado | X5: Leilão SFI | Y5: 102870 | Z5: 05/10/2026 | AA5: 09/10/2026 | AB5: 0046/0226 - CPA/RE | AC5: SIM | AD5: NAO | AE5: https://venda-imoveis.caixa.gov.br/sistema/detalhe-imovel.asp?hdnimovel=08787705612205
A6: 878770638651-9 | B6: BELA VISTA | C6: RUA SEBASTIAO ALZEMIRO DOS SANTOS,N. 387 APTO. 401 BL 11, BELA VISTA - CEP: 88137-640, PALHOCA - SANTA CATARINA | D6: 43.8 | E6: 252000 | F6: 151200 | G6: =D6*Premissas!$B$21*Premissas!$B$18 | H6: =F6*Premissas!$B$5 | I6: =F6*Premissas!$B$6 | J6: =F6*Premissas!$B$7 | K6: =Premissas!$B$9+Premissas!$B$10+Premissas!$B$11 | L6: =Premissas!$B$12 | M6: =D6*Premissas!$B$13 | N6: =Premissas!$B$14*Premissas!$B$15 | O6: =F6+H6+I6+J6+K6+L6+M6+N6 | P6: =G6*(1-Premissas!$B$17) | Q6: =P6-O6 | R6: =IFERROR(Q6/O6,0) | S6: =(P6/(1+Premissas!$B$19)-(K6+L6+M6+N6))/(1+(Premissas!$B$5+Premissas!$B$6+Premissas!$B$7)) | T6: =IFERROR((Premissas!$B$22-(K6+L6+M6+N6))/(Premissas!$B$23+(Premissas!$B$5+Premissas!$B$6+Premissas!$B$7)),0) | U6: =Premissas!$B$22-O6 | V6: =IF(U6<0,"Fora de alcance: falta caixa",IF(R6<Premissas!$B$19,"Reprova: margem abaixo do mínimo","Persegue")) | W6: Ocupado | X6: Leilão SFI | Y6: 103332 | Z6: 30/11/2026 | AA6: 04/12/2026 | AB6: 0052/0226 - CPA/RE | AC6: SIM | AD6: NAO | AE6: https://venda-imoveis.caixa.gov.br/sistema/detalhe-imovel.asp?hdnimovel=08787706386519
A7: 878771176139-0 | B7: BELA VISTA | C7: AVENIDA PAULO ROBERTO VIDAL,N. 475 APTO. 611 BL A, BELA VISTA - CEP: 88132-599, PALHOCA - SANTA CATARINA | D7: 48.49 | E7: 255000 | F7: 153000 | G7: =D7*Premissas!$B$21*Premissas!$B$18 | H7: =F7*Premissas!$B$5 | I7: =F7*Premissas!$B$6 | J7: =F7*Premissas!$B$7 | K7: =Premissas!$B$9+Premissas!$B$10+Premissas!$B$11 | L7: =Premissas!$B$12 | M7: =D7*Premissas!$B$13 | N7: =Premissas!$B$14*Premissas!$B$15 | O7: =F7+H7+I7+J7+K7+L7+M7+N7 | P7: =G7*(1-Premissas!$B$17) | Q7: =P7-O7 | R7: =IFERROR(Q7/O7,0) | S7: =(P7/(1+Premissas!$B$19)-(K7+L7+M7+N7))/(1+(Premissas!$B$5+Premissas!$B$6+Premissas!$B$7)) | T7: =IFERROR((Premissas!$B$22-(K7+L7+M7+N7))/(Premissas!$B$23+(Premissas!$B$5+Premissas!$B$6+Premissas!$B$7)),0) | U7: =Premissas!$B$22-O7 | V7: =IF(U7<0,"Fora de alcance: falta caixa",IF(R7<Premissas!$B$19,"Reprova: margem abaixo do mínimo","Persegue")) | W7: Ocupado | X7: Leilão SFI | Y7: 109903 | Z7: 30/11/2026 | AA7: 04/12/2026 | AB7: 0052/0226 - CPA/RE | AC7: SIM | AD7: NAO | AE7: https://venda-imoveis.caixa.gov.br/sistema/detalhe-imovel.asp?hdnimovel=08787711761390
A8: 878771588251-5 | B8: BELA VISTA | C8: AVENIDA PAULO ROBERTO VIDAL,N. 2050 APTO. 102 BL 11, BELA VISTA - CEP: 88132-599, PALHOCA - SANTA CATARINA | D8: 43.8 | E8: 258000 | F8: 168932.94 | G8: =D8*Premissas!$B$21*Premissas!$B$18 | H8: =F8*Premissas!$B$5 | I8: =F8*Premissas!$B$6 | J8: =F8*Premissas!$B$7 | K8: =Premissas!$B$9+Premissas!$B$10+Premissas!$B$11 | L8: =Premissas!$B$12 | M8: =D8*Premissas!$B$13 | N8: =Premissas!$B$14*Premissas!$B$15 | O8: =F8+H8+I8+J8+K8+L8+M8+N8 | P8: =G8*(1-Premissas!$B$17) | Q8: =P8-O8 | R8: =IFERROR(Q8/O8,0) | S8: =(P8/(1+Premissas!$B$19)-(K8+L8+M8+N8))/(1+(Premissas!$B$5+Premissas!$B$6+Premissas!$B$7)) | T8: =IFERROR((Premissas!$B$22-(K8+L8+M8+N8))/(Premissas!$B$23+(Premissas!$B$5+Premissas!$B$6+Premissas!$B$7)),0) | U8: =Premissas!$B$22-O8 | V8: =IF(U8<0,"Fora de alcance: falta caixa",IF(R8<Premissas!$B$19,"Reprova: margem abaixo do mínimo","Persegue")) | W8: Ocupado | X8: Leilão SFI | Y8: 116295 | Z8: 14/10/2026 | AA8: 20/10/2026 | AB8: 0048/0226 - CPA/RE | AC8: SIM | AD8: NAO | AE8: https://venda-imoveis.caixa.gov.br/sistema/detalhe-imovel.asp?hdnimovel=08787715882515

Sheet Todos os lotes
A1: Tudo que a varredura coletou
A2: Inclui os descartados, com o motivo. 20 lotes.
A4: Numero do imovel | B4: Status triagem | C4: Motivo do descarte | D4: Cidade | E4: Bairro | F4: Endereco | G4: Tipo | H4: Quartos | I4: Garagem | J4: Area total | K4: Area privativa | L4: Valor de avaliacao | M4: Preco 1o leilao | N4: Preco 2o leilao | O4: Desconto | P4: Situacao | Q4: Modalidade | R4: Matricula | S4: Comarca | T4: Data certame | U4: Leiloeiro | V4: Plataforma | W4: Formas de pagamento | X4: Condominio (regra) | Y4: Tributos (regra) | Z4: Aceita FGTS | AA4: Aceita financiamento | AB4: Edital PDF | AC4: Matricula PDF | AD4: Link
A5: 144441088173-5 | B5: DESCARTADO | C5: fora_do_bairro | D5: PALHOCA | E5: PAGANI | F5: RUA NAJLA CARONE GUEDERT,N. 27 APTO. 102 TIPO E, VG 111, PAGANI - CEP: 88132-150, PALHOCA - SANTA CATARINA | G5: Apartamento | H5: 2 | I5: 1 | J5: 107.12 | K5: 64.3 | L5: 550500 | M5: 550500 | N5: 330300 | O5: 0.4 | P5: Ocupado | Q5: Leilão SFI | R5: 83217, 83122 | S5: PALHOCA-SC | T5: 05/10/2026 / 09/10/2026 | U5: Andressa Sedrez Terres Tonial Ferreira | V5: www.tonialleiloes.com.br | W5: Recursos próprios. Permite utilização de FGTS. Consulte condições e enquadramento. | X5: Sob responsabilidade do comprador. | Y5: Sob responsabilidade do comprador. | Z5: SIM | AA5: NAO | AB5: https://venda-imoveis.caixa.gov.br/editais/EL00460226CPARE.PDF | AC5: https://venda-imoveis.caixa.gov.br/editais/matricula/SC/1444410881735.pdf | AD5: https://venda-imoveis.caixa.gov.br/sistema/detalhe-imovel.asp?hdnimovel=01444410881735
A6: 878770561220-5 | B6: TRIAGEM | D6: PALHOCA | E6: BELA VISTA | F6: RUA SEBASTIAO ALZEMIRO DOS SANTOS,N. 387 APTO. 104 BL 10 VG182, BELA VISTA - CEP: 88137-640, PALHOCA - SANTA CATARINA | G6: Apartamento | H6: 2 | I6: 1 | J6: 80.51 | K6: 43.8 | L6: 252000 | M6: 252000 | N6: 151200 | O6: 0.4 | P6: Ocupado | Q6: Leilão SFI | R6: 102870 | S6: PALHOCA-SC | T6: 05/10/2026 / 09/10/2026 | U6: Andressa Sedrez Terres Tonial Ferreira | V6: www.tonialleiloes.com.br | W6: Recursos próprios. Permite utilização de FGTS. Consulte condições e enquadramento. | X6: Sob responsabilidade do comprador. | Y6: Sob responsabilidade do comprador. | Z6: SIM | AA6: NAO | AB6: https://venda-imoveis.caixa.gov.br/editais/EL00460226CPARE.PDF | AC6: https://venda-imoveis.caixa.gov.br/editais/matricula/SC/8787705612205.pdf | AD6: https://venda-imoveis.caixa.gov.br/sistema/detalhe-imovel.asp?hdnimovel=08787705612205
A7: 878770638651-9 | B7: TRIAGEM | D7: PALHOCA | E7: BELA VISTA | F7: RUA SEBASTIAO ALZEMIRO DOS SANTOS,N. 387 APTO. 401 BL 11, BELA VISTA - CEP: 88137-640, PALHOCA - SANTA CATARINA | G7: Apartamento | H7: 2 | I7: 1 | J7: 80.51 | K7: 43.8 | L7: 252000 | M7: 252000 | N7: 151200 | O7: 0.4 | P7: Ocupado | Q7: Leilão SFI | R7: 103332 | S7: PALHOCA-SC | T7: 30/11/2026 / 04/12/2026 | U7: JONAS GABRIEL ANTUNES MOREIRA | V7: www.mgl.com.br | W7: Recursos próprios. Permite utilização de FGTS. Consulte condições e enquadramento. | X7: Sob responsabilidade do comprador. | Y7: Sob responsabilidade do comprador. | Z7: SIM | AA7: NAO | AB7: https://venda-imoveis.caixa.gov.br/editais/EL00520226CPARE.PDF | AC7: https://venda-imoveis.caixa.gov.br/editais/matricula/SC/8787706386519.pdf | AD7: https://venda-imoveis.caixa.gov.br/sistema/detalhe-imovel.asp?hdnimovel=08787706386519
A8: 878771159497-3 | B8: DESCARTADO | C8: fora_do_bairro | D8: PALHOCA | E8: PRAIA DE FORA | F8: AVENIDA ARCANJO CANDIDO DA SILVA,N. 702 APTO. 206 PAV 02 BL 02, PRAIA DE FORA - CEP: 88138-300, PALHOCA - SANTA CATARINA | G8: Apartamento | H8: 2 | I8: 1 | J8: 64.12 | K8: 49.07 | L8: 280000 | M8: 280000 | N8: 168000 | O8: 0.4 | P8: Ocupado | Q8: Leilão SFI | R8: 91884 | S8: PALHOCA-SC | T8: 24/11/2026 / 30/11/2026 | U8: TATIANA PAULA ZANI DE SOUSA | V8: www.liderleiloes.com.br | W8: Recursos próprios. Permite utilização de FGTS. Consulte condições e enquadramento. | X8: Sob responsabilidade do comprador. | Y8: Sob responsabilidade do comprador. | Z8: SIM | AA8: NAO | AB8: https://venda-imoveis.caixa.gov.br/editais/EL00510226CPARE.PDF | AC8: https://venda-imoveis.caixa.gov.br/editais/matricula/SC/8787711594973.pdf | AD8: https://venda-imoveis.caixa.gov.br/sistema/detalhe-imovel.asp?hdnimovel=08787711594973
A9: 878771176139-0 | B9: TRIAGEM | D9: PALHOCA | E9: BELA VISTA | F9: AVENIDA PAULO ROBERTO VIDAL,N. 475 APTO. 611 BL A, BELA VISTA - CEP: 88132-599, PALHOCA - SANTA CATARINA | G9: Apartamento | H9: 2 | I9: 1 | J9: 74.71 | K9: 48.49 | L9: 255000 | M9: 255000 | N9: 153000 | O9: 0.4 | P9: Ocupado | Q9: Leilão SFI | R9: 109903 | S9: PALHOCA-SC | T9: 30/11/2026 / 04/12/2026 | U9: JONAS GABRIEL ANTUNES MOREIRA | V9: www.mgl.com.br | W9: Recursos próprios. Permite utilização de FGTS. Consulte condições e enquadramento. | X9: Sob responsabilidade do comprador. | Y9: Sob responsabilidade do comprador. | Z9: SIM | AA9: NAO | AB9: https://venda-imoveis.caixa.gov.br/editais/EL00520226CPARE.PDF | AC9: https://venda-imoveis.caixa.gov.br/editais/matricula/SC/8787711761390.pdf | AD9: https://venda-imoveis.caixa.gov.br/sistema/detalhe-imovel.asp?hdnimovel=08787711761390
A10: 878771537674-1 | B10: DESCARTADO | C10: fora_do_bairro | D10: PALHOCA | E10: SAO SEBASTIAO | F10: RUA RAULINO MARTINHO DIAS,N. 29 APTO. AP 304 BL 06, SAO SEBASTIAO - CEP: 88136-351, PALHOCA - SANTA CATARINA | G10: Apartamento | H10: 2 | I10: 1 | J10: 75.45 | K10: 52.85 | L10: 310000 | M10: 310000 | N10: 186000 | O10: 0.4 | P10: Ocupado | Q10: Leilão SFI | R10: 115776 | S10: PALHOCA-SC | T10: 02/10/2026 / 08/10/2026 | U10: MARCOS ROBERTO TORRES | V10: www.3torresleiloes.com.br | W10: Recursos próprios. Permite utilização de FGTS. Consulte condições e enquadramento. | X10: Sob responsabilidade do comprador. | Y10: Sob responsabilidade do comprador. | Z10: SIM | AA10: NAO | AB10: https://venda-imoveis.caixa.gov.br/editais/EL00450226CPARE.PDF | AC10: https://venda-imoveis.caixa.gov.br/editais/matricula/SC/8787715376741.pdf | AD10: https://venda-imoveis.caixa.gov.br/sistema/detalhe-imovel.asp?hdnimovel=08787715376741
A11: 878771588251-5 | B11: TRIAGEM | D11: PALHOCA | E11: BELA VISTA | F11: AVENIDA PAULO ROBERTO VIDAL,N. 2050 APTO. 102 BL 11, BELA VISTA - CEP: 88132-599, PALHOCA - SANTA CATARINA | G11: Apartamento | H11: 2 | I11: 1 | J11: 50.87 | K11: 43.8 | L11: 258000 | M11: 258000 | N11: 168932.94 | O11: 0.3452 | P11: Ocupado | Q11: Leilão SFI | R11: 116295 | S11: PALHOCA-SC | T11: 14/10/2026 / 20/10/2026 | U11: CIRLEI FREITAS BALBINO DA SILVA | V11: www.globoleiloes.com.br | W11: Recursos próprios. Permite utilização de FGTS. Consulte condições e enquadramento. | X11: Sob responsabilidade do comprador. | Y11: Sob responsabilidade do comprador. | Z11: SIM | AA11: NAO | AB11: https://venda-imoveis.caixa.gov.br/editais/EL00480226CPARE.PDF | AC11: https://venda-imoveis.caixa.gov.br/editais/matricula/SC/8787715882515.pdf | AD11: https://venda-imoveis.caixa.gov.br/sistema/detalhe-imovel.asp?hdnimovel=08787715882515
A12: 144441718579-3 | B12: DESCARTADO | C12: fora_da_cidade;fora_do_bairro | D12: SAO_JOSE | E12: SERTAO DO MARUIM | F12: RUA ZILMA OLIVEIRA DA SILVA,N. SN LT 10 QD 03, SERTAO DO MARUIM - CEP: 88122-459, SAO JOSE - SANTA CATARINA | G12: Casa | H12: 2 | J12: 200 | K12: 200 | L12: 1330000 | M12: 1330000 | N12: 798000 | O12: 0.4 | P12: Ocupado | Q12: Leilão SFI | R12: 133028 | S12: SAO JOSE-SC | T12: 23/11/2026 / 27/11/2026 | U12: RODRIGO SCHMITZ | V12: www.hammer.lel.br | W12: Exclusivamente à vista (somente recursos próprios). | X12: Sob responsabilidade do comprador. | Y12: Sob responsabilidade do comprador. | Z12: NAO | AA12: NAO | AB12: https://venda-imoveis.caixa.gov.br/editais/EL00500226CPARE.PDF | AC12: https://venda-imoveis.caixa.gov.br/editais/matricula/SC/1444417185793.pdf | AD12: https://venda-imoveis.caixa.gov.br/sistema/detalhe-imovel.asp?hdnimovel=01444417185793
A13: 144441762824-5 | B13: DESCARTADO | C13: fora_da_cidade;fora_do_bairro | D13: SAO_JOSE | E13: FORQUILHINHA | F13: RUA PEDRO PAULO DE ABREU,N. 801 APTO. 404 BL A VG 16, FORQUILHINHA - CEP: 88106-785, SAO JOSE - SANTA CATARINA | G13: Apartamento | H13: 3 | I13: 1 | J13: 80.44 | K13: 68.77 | L13: 305000 | M13: 305011.21 | N13: 185854.53 | O13: 0.3906 | P13: Ocupado | Q13: Leilão SFI | R13: 76157 | S13: SAO JOSE-SC | T13: 20/10/2026 / 26/10/2026 | U13: EDUARDO SCHMITZ | V13: www.clicleiloes.com.br | W13: Recursos próprios. Permite utilização de FGTS. Consulte condições e enquadramento. | X13: Sob responsabilidade do comprador. | Y13: Sob responsabilidade do comprador. | Z13: SIM | AA13: NAO | AB13: https://venda-imoveis.caixa.gov.br/editais/EL00490226CPARE.PDF | AC13: https://venda-imoveis.caixa.gov.br/editais/matricula/SC/1444417628245.pdf | AD13: https://venda-imoveis.caixa.gov.br/sistema/detalhe-imovel.asp?hdnimovel=01444417628245
A14: 160000016077-0 | B14: DESCARTADO | C14: fora_da_cidade;fora_do_bairro | D14: SAO_JOSE | E14: AREIAS | F14: RUA AUGUSTO JORGE BRUGGEMANN,N. 550 APTO. 301 LT 10 QD 09, AREIAS - CEP: 88113-823, SAO JOSE - SANTA CATARINA | G14: Apartamento | H14: 3 | I14: 2 | J14: 250.33 | K14: 186.64 | L14: 872000 | M14: 0 | N14: 0 | O14: 0.3627 | P14: Ocupado | Q14: Venda Online | R14: 129686 | S14: SAO JOSE-SC | W14: Recursos próprios. Permite utilização de FGTS. Consulte condições e enquadramento. Permite financiamento - somente SBPE. Consulte condições antes de efetuar a proposta. | X14: Sob responsabilidade do comprador, até o limite de 10% em relação ao valor de avaliação do imóvel. A CAIXA realizará o pagamento apenas do valor que exceder o limite de 10% do valor de avaliação. | Y14: Sob responsabilidade do comprador, quando o débito for inferior a 10% do valor de avaliação. A CAIXA paga integralmente quando o débito for superior a 10% do valor de avaliação. | Z14: SIM | AA14: SIM | AC14: https://venda-imoveis.caixa.gov.br/editais/matricula/SC/1600000160770.pdf | AD14: https://venda-imoveis.caixa.gov.br/sistema/detalhe-imovel.asp?hdnimovel=01600000160770
A15: 844441577446-3 | B15: DESCARTADO | C15: fora_da_cidade;fora_do_bairro | D15: SAO_JOSE | E15: FORQUILHAS LESTE | F15: RUA OLINDO CORTINA,N. 251 LOTE 15 QUADRA 01, FORQUILHAS LESTE - CEP: 88107-564, SAO JOSE - SANTA CATARINA | G15: Casa | H15: 2 | I15: 1 | J15: 66.87 | K15: 53.4 | L15: 337000 | M15: 337000 | N15: 202200 | O15: 0.4 | P15: Ocupado | Q15: Leilão SFI | R15: 136507 | S15: SAO JOSE-SC | T15: 24/11/2026 / 30/11/2026 | U15: TATIANA PAULA ZANI DE SOUSA | V15: www.liderleiloes.com.br | W15: Recursos próprios. Permite utilização de FGTS. Consulte condições e enquadramento. | X15: Sob responsabilidade do comprador. | Y15: Sob responsabilidade do comprador. | Z15: SIM | AA15: NAO | AB15: https://venda-imoveis.caixa.gov.br/editais/EL00510226CPARE.PDF | AC15: https://venda-imoveis.caixa.gov.br/editais/matricula/SC/8444415774463.pdf | AD15: https://venda-imoveis.caixa.gov.br/sistema/detalhe-imovel.asp?hdnimovel=08444415774463
A16: 855550750226-7 | B16: DESCARTADO | C16: fora_da_cidade;fora_do_bairro | D16: SAO_JOSE | E16: FORQUILHINHA | F16: AVENIDA VALDEMAR SCHMIDT,N. 1057 APTO. 04, FORQUILHINHA - CEP: 88107-020, SAO JOSE - SANTA CATARINA | G16: Apartamento | H16: 2 | J16: 77.17 | K16: 63.23 | L16: 325000 | M16: 325000 | N16: 195000 | O16: 0.4 | P16: Ocupado | Q16: Leilão SFI | R16: 84865 | S16: SAO JOSE-SC | T16: 23/11/2026 / 27/11/2026 | U16: RODRIGO SCHMITZ | V16: www.hammer.lel.br | W16: Exclusivamente à vista (somente recursos próprios). | X16: Sob responsabilidade do comprador. | Y16: Sob responsabilidade do comprador. | Z16: NAO | AA16: NAO | AB16: https://venda-imoveis.caixa.gov.br/editais/EL00500226CPARE.PDF | AC16: https://venda-imoveis.caixa.gov.br/editais/matricula/SC/8555507502267.pdf | AD16: https://venda-imoveis.caixa.gov.br/sistema/detalhe-imovel.asp?hdnimovel=08555507502267
A17: 855553340804-3 | B17: DESCARTADO | C17: fora_da_cidade;fora_do_bairro | D17: SAO_JOSE | E17: REAL PARQUE | F17: RUA ZIONI BERKENBROCK,N. 386 APTO. 102 BL B16, REAL PARQUE - CEP: 88113-500, SAO JOSE - SANTA CATARINA | G17: Apartamento | H17: 2 | J17: 54.72 | K17: 48.2 | L17: 305000 | M17: 305000 | N17: 183000 | O17: 0.4 | P17: Ocupado | Q17: Leilão SFI | R17: 11217 | S17: SAO JOSE-SC | T17: 23/11/2026 / 27/11/2026 | U17: RODRIGO SCHMITZ | V17: www.hammer.lel.br | W17: Recursos próprios. Permite utilização de FGTS. Consulte condições e enquadramento. | X17: Sob responsabilidade do comprador. | Y17: Sob responsabilidade do comprador. | Z17: SIM | AA17: NAO | AB17: https://venda-imoveis.caixa.gov.br/editais/EL00500226CPARE.PDF | AC17: https://venda-imoveis.caixa.gov.br/editais/matricula/SC/8555533408043.pdf | AD17: https://venda-imoveis.caixa.gov.br/sistema/detalhe-imovel.asp?hdnimovel=08555533408043
A18: 855553592682-3 | B18: DESCARTADO | C18: fora_da_cidade;fora_do_bairro | D18: SAO_JOSE | E18: FORQUILHAS LESTE | F18: RUA ANTONIO JOVITA DUARTE,N. 3147 APTO. 101 PAV TERREO BL 10, FORQUILHAS LESTE - CEP: 88107-100, SAO JOSE - SANTA CATARINA | G18: Apartamento | H18: 2 | I18: 1 | J18: 49.6 | K18: 44.78 | L18: 265000 | M18: 265000 | N18: 159000 | O18: 0.4 | P18: Ocupado | Q18: Leilão SFI | R18: 106751 | S18: SAO JOSE-SC | T18: 24/11/2026 / 30/11/2026 | U18: TATIANA PAULA ZANI DE SOUSA | V18: www.liderleiloes.com.br | W18: Recursos próprios. Permite utilização de FGTS. Consulte condições e enquadramento. | X18: Sob responsabilidade do comprador. | Y18: Sob responsabilidade do comprador. | Z18: SIM | AA18: NAO | AB18: https://venda-imoveis.caixa.gov.br/editais/EL00510226CPARE.PDF | AC18: https://venda-imoveis.caixa.gov.br/editais/matricula/SC/8555535926823.pdf | AD18: https://venda-imoveis.caixa.gov.br/sistema/detalhe-imovel.asp?hdnimovel=08555535926823
A19: 878771222509-2 | B19: DESCARTADO | C19: fora_da_cidade;fora_do_bairro | D19: SAO_JOSE | E19: AREIAS | F19: RUA LOURIVAL LUIZ GOMES,N. 315 APTO. 203 BL 19 VAGA 336, AREIAS - CEP: 88113-845, SAO JOSE - SANTA CATARINA | G19: Apartamento | H19: 2 | I19: 1 | J19: 75.55 | K19: 40.28 | L19: 250000 | M19: 250000 | N19: 154256.96 | O19: 0.383 | P19: Ocupado | Q19: Leilão SFI | R19: 2772 | S19: SAO JOSE-SC | T19: 14/10/2026 / 20/10/2026 | U19: CIRLEI FREITAS BALBINO DA SILVA | V19: www.globoleiloes.com.br | W19: Recursos próprios. Permite utilização de FGTS. Consulte condições e enquadramento. | X19: Sob responsabilidade do comprador. | Y19: Sob responsabilidade do comprador. | Z19: SIM | AA19: NAO | AB19: https://venda-imoveis.caixa.gov.br/editais/EL00480226CPARE.PDF | AC19: https://venda-imoveis.caixa.gov.br/editais/matricula/SC/8787712225092.pdf | AD19: https://venda-imoveis.caixa.gov.br/sistema/detalhe-imovel.asp?hdnimovel=08787712225092
A20: 878771317103-4 | B20: DESCARTADO | C20: fora_da_cidade;fora_do_bairro | D20: SAO_JOSE | E20: SERTAO DO MARUIM | F20: RUA VIDAL VICENTE ANDRADE,N. 1171 APTO. 404 BL 2 VG 264, SERTAO DO MARUIM - CEP: 88121-810, SAO JOSE - SANTA CATARINA | G20: Apartamento | H20: 2 | I20: 1 | J20: 76.62 | K20: 40.28 | L20: 250000 | M20: 250000 | N20: 152483.93 | O20: 0.3901 | P20: Ocupado | Q20: Leilão SFI | R20: 148810 | S20: SAO JOSE-SC | T20: 23/11/2026 / 27/11/2026 | U20: RODRIGO SCHMITZ | V20: www.hammer.lel.br | W20: Recursos próprios. Permite utilização de FGTS. Consulte condições e enquadramento. | X20: Sob responsabilidade do comprador. | Y20: Sob responsabilidade do comprador. | Z20: SIM | AA20: NAO | AB20: https://venda-imoveis.caixa.gov.br/editais/EL00500226CPARE.PDF | AC20: https://venda-imoveis.caixa.gov.br/editais/matricula/SC/8787713171034.pdf | AD20: https://venda-imoveis.caixa.gov.br/sistema/detalhe-imovel.asp?hdnimovel=08787713171034
A21: 878771529055-3 | B21: DESCARTADO | C21: fora_da_cidade;fora_do_bairro | D21: SAO_JOSE | E21: SERTAO DO MARUIM | F21: RUA VALTELINO LEAL DEMETRIO,N. 18 APTO. 303 BL 04 PAV 03, SERTAO DO MARUIM - CEP: 88122-150, SAO JOSE - SANTA CATARINA | G21: Apartamento | H21: 2 | I21: 1 | J21: 57.16 | K21: 48.08 | L21: 285000 | M21: 285000 | N21: 199679.4 | O21: 0.2994 | P21: Ocupado | Q21: Leilão SFI | R21: 148074 | S21: SAO JOSE-SC | T21: 24/11/2026 / 30/11/2026 | U21: TATIANA PAULA ZANI DE SOUSA | V21: www.liderleiloes.com.br | W21: Recursos próprios. Permite utilização de FGTS. Consulte condições e enquadramento. | X21: Sob responsabilidade do comprador. | Y21: Sob responsabilidade do comprador. | Z21: SIM | AA21: NAO | AB21: https://venda-imoveis.caixa.gov.br/editais/EL00510226CPARE.PDF | AC21: https://venda-imoveis.caixa.gov.br/editais/matricula/SC/8787715290553.pdf | AD21: https://venda-imoveis.caixa.gov.br/sistema/detalhe-imovel.asp?hdnimovel=08787715290553
A22: 000001028634-4 | B22: DESCARTADO | C22: fora_da_cidade;fora_do_bairro | D22: FLORIANOPOLIS | E22: ESTREITO | F22: AVENIDA GOVERNADOR IVO SILVEIRA,N. 2487, ESTREITO - CEP: 88085-001, FLORIANOPOLIS - SANTA CATARINA | G22: Comercial | J22: 0 | K22: 577.1 | L22: 3035000 | M22: 0 | N22: 0 | O22: 0.3627 | P22: Ocupado | Q22: Venda Online | R22: 4894 | S22: FLORIANOPOLIS-SC | W22: Recursos próprios. Permite financiamento - somente SBPE. Consulte condições antes de efetuar a proposta. | X22: Sob responsabilidade do comprador, até o limite de 10% em relação ao valor de avaliação do imóvel. A CAIXA realizará o pagamento apenas do valor que exceder o limite de 10% do valor de avaliação. | Y22: Sob responsabilidade do comprador, quando o débito for inferior a 10% do valor de avaliação. A CAIXA paga integralmente quando o débito for superior a 10% do valor de avaliação. | Z22: NAO | AA22: SIM | AC22: https://venda-imoveis.caixa.gov.br/editais/matricula/SC/0000010286344.pdf | AD22: https://venda-imoveis.caixa.gov.br/sistema/detalhe-imovel.asp?hdnimovel=00000010286344
A23: 144440299841-6 | B23: DESCARTADO | C23: fora_da_cidade;fora_do_bairro | D23: FLORIANOPOLIS | E23: CENTRO | F23: RUA DESEMBARGADOR ARNO HOESCHL,N. 121 APTO. 102, BOX 15, CENTRO - CEP: 88015-620, FLORIANOPOLIS - SANTA CATARINA | G23: Apartamento | H23: 3 | I23: 1 | J23: 149.18 | K23: 115.49 | L23: 1270000 | M23: 0 | N23: 0 | O23: 0.3627 | P23: Ocupado | Q23: Venda Online | R23: 31204, 31205 | S23: FLORIANOPOLIS-SC | W23: Exclusivamente à vista (somente recursos próprios). | X23: Sob responsabilidade do comprador, até o limite de 10% em relação ao valor de avaliação do imóvel. A CAIXA realizará o pagamento apenas do valor que exceder o limite de 10% do valor de avaliação. | Y23: Sob responsabilidade do comprador, quando o débito for inferior a 10% do valor de avaliação. A CAIXA paga integralmente quando o débito for superior a 10% do valor de avaliação. | Z23: NAO | AA23: NAO | AC23: https://venda-imoveis.caixa.gov.br/editais/matricula/SC/1444402998416.pdf | AD23: https://venda-imoveis.caixa.gov.br/sistema/detalhe-imovel.asp?hdnimovel=01444402998416
A24: 810110001631-4 | B24: DESCARTADO | C24: fora_da_cidade;fora_do_bairro | D24: FLORIANOPOLIS | E24: CORREGO GRANDE | F24: RUA MAESTRO ALDO KRIEGER,N. 138 APTO. 102, BOX DE GARAGEM N° 17, CORREGO GRANDE - CEP: 88037-500, FLORIANOPOLIS - SANTA CATARINA | G24: Apartamento | H24: 3 | I24: 1 | J24: 0 | K24: 83.47 | L24: 800000 | M24: 800000 | N24: 480000 | O24: 0.4 | P24: Ocupado | Q24: Leilão SFI | R24: 38298, 38299 | S24: FLORIANOPOLIS-SC | T24: 30/11/2026 / 04/12/2026 | U24: JONAS GABRIEL ANTUNES MOREIRA | V24: www.mgl.com.br | W24: Recursos próprios. Permite financiamento - somente SBPE. Consulte condições antes de efetuar a proposta. | X24: Sob responsabilidade do comprador. | Y24: Sob responsabilidade do comprador. | Z24: NAO | AA24: SIM | AB24: https://venda-imoveis.caixa.gov.br/editais/EL00520226CPARE.PDF | AC24: https://venda-imoveis.caixa.gov.br/editais/matricula/SC/8101100016314.pdf | AD24: https://venda-imoveis.caixa.gov.br/sistema/detalhe-imovel.asp?hdnimovel=08101100016314

Sheet Comparáveis
A1: Anúncios ativos que formam o VVR
A2: Preço pedido, não preço fechado. 79 anúncios. Levantado em 23/09/2026 (15 DIAS — levantamento vencido; a fonte de anuncios respondeu com bloqueio e o R$/m2 segue congelado nessa data).
A4: grupo | B4: tipo | C4: quartos | D4: area | E4: preco | F4: condominio | G4: anunciante | H4: url
A5: venda_apto | B5: Apartamento | C5: 2 | D5: 52 | E5: 275000 | F5: 300.0 | G5: Marcelo Paim Corretor | H5: https://www.imoveis-sc.com.br/palhoca/comprar/apartamento/bela-vista/apartamento-a-venda-com-2-quartos-52m2-no-bela-vista-palhoca-9697019.html
A6: venda_apto | B6: Apartamento | C6: 2 | D6: 50 | E6: 240000 | F6: 325.0 | G6: Marcelo Paim Corretor | H6: https://www.imoveis-sc.com.br/palhoca/comprar/apartamento/bela-vista/apartamento-a-venda-com-2-quartos-50m2-no-bela-vista-palhoca-9635415.html
A7: venda_apto | B7: Apartamento | C7: 2 | D7: 44.49 | E7: 245000 | F7: 450.0 | G7: Crédito Real Village | H7: https://www.imoveis-sc.com.br/palhoca/comprar/apartamento/bela-vista/apartamento-a-venda-com-2-quartos-no-bela-vista-palhoca-8718653.html
A8: venda_apto | B8: Apartamento | C8: 2 | D8: 48 | E8: 286500 | F8: 399.0 | G8: Crédito Real Pedra Branca | H8: https://www.imoveis-sc.com.br/palhoca/comprar/apartamento/bela-vista/apartamento-a-venda-com-2-quartos-48m2-no-bela-vista-palhoca-9086637.html
A9: venda_apto | B9: Apartamento | C9: 2 | D9: 47.8 | E9: 318000 | G9: Crédito Real Imob48 | H9: https://www.imoveis-sc.com.br/palhoca/comprar/apartamento/bela-vista/apartamento-a-venda-com-2-quartos-no-bela-vista-palhoca-8717235.html
A10: venda_apto | B10: Apartamento | C10: 2 | D10: 47.21 | E10: 270000 | G10: Crédito Real Imob48 | H10: https://www.imoveis-sc.com.br/palhoca/comprar/apartamento/bela-vista/apartamento-a-venda-com-2-quartos-no-bela-vista-palhoca-8717209.html
A11: venda_apto | B11: Apartamento | C11: 2 | D11: 45.75 | E11: 290000 | F11: 311.0 | G11: Crédito Real Grande Floripa | H11: https://www.imoveis-sc.com.br/palhoca/comprar/apartamento/bela-vista/apartamento-a-venda-com-2-quartos-no-bela-vista-palhoca-8716165.html
A12: venda_apto | B12: Apartamento | C12: 2 | D12: 56 | E12: 325000 | G12: Crédito Real Grande Floripa | H12: https://www.imoveis-sc.com.br/palhoca/comprar/apartamento/bela-vista/apartamento-a-venda-com-2-quartos-no-bela-vista-palhoca-8716218.html
A13: venda_apto | B13: Apartamento | C13: 2 | D13: 43.8 | E13: 259000 | F13: 500.0 | G13: Crédito Real Costa Sul | H13: https://www.imoveis-sc.com.br/palhoca/comprar/apartamento/bela-vista/apartamento-a-venda-com-2-quartos-no-bela-vista-palhoca-8656924.html
A14: venda_apto | B14: Apartamento | C14: 2 | D14: 59.04 | E14: 350000 | F14: 384.0 | G14: Crédito Real Iflex | H14: https://www.imoveis-sc.com.br/palhoca/comprar/apartamento/bela-vista/apartamento-a-venda-com-2-quartos-no-bela-vista-palhoca-8539046.html
A15: venda_apto | B15: Apartamento | C15: 2 | D15: 46 | E15: 230000 | F15: 325.0 | G15: Crédito Real Continente | H15: https://www.imoveis-sc.com.br/palhoca/comprar/apartamento/bela-vista/apartamento-a-venda-com-2-quartos-no-bela-vista-palhoca-8655868.html
A16: venda_apto | B16: Apartamento | C16: 2 | D16: 52 | E16: 350000 | F16: 450.0 | G16: Crédito Real Imob48 | H16: https://www.imoveis-sc.com.br/palhoca/comprar/apartamento/bela-vista/apartamento-a-venda-com-2-quartos-60m2-no-bela-vista-palhoca-9021286.html
A17: venda_apto | B17: Apartamento | C17: 2 | D17: 45.61 | E17: 260000 | F17: 315.0 | G17: Crédito Real Imob48 | H17: https://www.imoveis-sc.com.br/palhoca/comprar/apartamento/bela-vista/apartamento-a-venda-com-2-quartos-no-bela-vista-palhoca-8875918.html
A18: venda_apto | B18: Apartamento | C18: 2 | D18: 45.59 | E18: 335000 | F18: 400.0 | G18: Crédito Real Dorea | H18: https://www.imoveis-sc.com.br/palhoca/comprar/apartamento/bela-vista/apartamento-a-venda-com-2-quartos-no-bela-vista-palhoca-8656723.html
A19: venda_apto | B19: Apartamento | C19: 2 | D19: 43 | E19: 256000 | G19: Crédito Real Biguaçu | H19: https://www.imoveis-sc.com.br/palhoca/comprar/apartamento/bela-vista/apartamento-a-venda-com-2-quartos-no-bela-vista-palhoca-8656242.html
A20: venda_apto | B20: Apartamento | C20: 2 | D20: 50 | E20: 340000 | F20: 350.0 | G20: Crédito Real Iflex | H20: https://www.imoveis-sc.com.br/palhoca/comprar/apartamento/bela-vista/apartamento-a-venda-com-2-quartos-no-bela-vista-palhoca-8538546.html
A21: venda_apto | B21: Apartamento | C21: 2 | D21: 54.03 | E21: 275000 | G21: Crédito Real Imob48 | H21: https://www.imoveis-sc.com.br/palhoca/comprar/apartamento/bela-vista/apartamento-a-venda-com-2-quartos-no-bela-vista-palhoca-8717239.html
A22: venda_apto | B22: Apartamento | C22: 2 | D22: 53 | E22: 245000 | F22: 300.0 | G22: Auxiliadora Predial - Florianópolis - Lagoa da Conceição | H22: https://www.imoveis-sc.com.br/palhoca/comprar/apartamento/bela-vista/apartamento-a-venda-com-2-quartos-no-bela-vista-palhoca-1464711.html
A23: venda_apto | B23: Apartamento | C23: 2 | D23: 0 | E23: 260000 | F23: 311.0 | G23: Auxiliadora Predial - Florianópolis Pedra Branca | H23: https://www.imoveis-sc.com.br/palhoca/comprar/apartamento/bela-vista/apartamento-a-venda-com-2-quartos-no-bela-vista-palhoca-1475338.html
A24: venda_apto | B24: Apartamento | C24: 2 | D24: 44 | E24: 259000 | F24: 350.0 | G24: Auxiliadora Predial - Florianópolis - São José e Campinas | H24: https://www.imoveis-sc.com.br/palhoca/comprar/apartamento/bela-vista/apartamento-a-venda-com-2-quartos-no-bela-vista-palhoca-1488303.html
A25: venda_apto | B25: Apartamento | C25: 2 | D25: 48.74 | E25: 278000 | F25: 445.0 | G25: Auxiliadora Predial - Florianópolis Pedra Branca | H25: https://www.imoveis-sc.com.br/palhoca/comprar/apartamento/bela-vista/apartamento-a-venda-com-2-quartos-no-bela-vista-palhoca-1461812.html
A26: venda_apto | B26: Apartamento | C26: 2 | D26: 53 | E26: 285000 | F26: 479.0 | G26: Auxiliadora Predial - Florianópolis - São José e Campinas | H26: https://www.imoveis-sc.com.br/palhoca/comprar/apartamento/bela-vista/apartamento-a-venda-com-2-quartos-no-bela-vista-palhoca-4652541.html
A27: venda_apto | B27: Apartamento | C27: 2 | D27: 62 | E27: 350000 | F27: 530.0 | G27: Auxiliadora Predial - Pinheira | H27: https://www.imoveis-sc.com.br/palhoca/comprar/apartamento/bela-vista/apartamento-a-venda-com-2-quartos-no-bela-vista-palhoca-1466475.html
A28: venda_apto | B28: Apartamento | C28: 2 | D28: 61 | E28: 270000 | F28: 400.0 | G28: Qualité Imóveis Exclusivos | H28: https://www.imoveis-sc.com.br/palhoca/comprar/apartamento/bela-vista/apartamento-a-venda-com-2-quartos-no-bela-vista-palhoca-3007920.html
A29: venda_apto | B29: Apartamento | C29: 2 | D29: 53 | E29: 265000 | F29: 446.0 | G29: Auxiliadora Predial - Florianópolis Centro Histórico | H29: https://www.imoveis-sc.com.br/palhoca/comprar/apartamento/bela-vista/apartamento-a-venda-com-2-quartos-no-bela-vista-palhoca-1394244.html
A30: venda_apto | B30: Apartamento | C30: 2 | D30: 43.3 | E30: 285000 | F30: 445.0 | G30: Auxiliadora Predial - Florianópolis - Sul da Ilha | H30: https://www.imoveis-sc.com.br/palhoca/comprar/apartamento/bela-vista/apartamento-a-venda-com-2-quartos-no-bela-vista-palhoca-4159747.html
A31: venda_casa | B31: Casa | C31: 2 | D31: 0 | E31: 339200 | G31: Crédito Real Biguaçu | H31: https://www.imoveis-sc.com.br/palhoca/comprar/casa/bela-vista/casa-a-venda-com-2-quartos-48m2-no-bela-vista-palhoca-9595576.html
A32: venda_casa | B32: Casa | C32: 2 | D32: 0 | E32: 365000 | G32: Crédito Real Imob48 | H32: https://www.imoveis-sc.com.br/palhoca/comprar/casa/bela-vista/casa-a-venda-com-2-quartos-50m2-no-bela-vista-palhoca-9319927.html
A33: venda_casa | B33: Casa | C33: 2 | D33: 0 | E33: 451579 | G33: INVESTIMENTO IMOBILIÁRIO | H33: https://www.imoveis-sc.com.br/palhoca/comprar/casa/bela-vista/casa-a-venda-com-2-quartos-76m2-no-bela-vista-palhoca-9540507.html
A34: venda_casa | B34: Casa | C34: 3 | D34: 0 | E34: 820000 | G34: Crédito Real Grande Floripa | H34: https://www.imoveis-sc.com.br/palhoca/comprar/casa/bela-vista/casa-a-venda-com-3-quartos-no-bela-vista-palhoca-8716501.html
A35: venda_casa | B35: Casa | C35: 2 | D35: 0 | E35: 492000 | G35: Crédito Real Grande Floripa | H35: https://www.imoveis-sc.com.br/palhoca/comprar/casa/bela-vista/casa-a-venda-com-2-quartos-no-bela-vista-palhoca-8716429.html
A36: venda_casa | B36: Casa | C36: 2 | D36: 0 | E36: 360400 | G36: Crédito Real Imob48 | H36: https://www.imoveis-sc.com.br/palhoca/comprar/casa/bela-vista/casa-a-venda-com-2-quartos-no-bela-vista-palhoca-8121103.html
A37: venda_casa | B37: Casa | C37: 2 | D37: 0 | E37: 370000 | G37: Crédito Real Imob48 | H37: https://www.imoveis-sc.com.br/palhoca/comprar/casa/bela-vista/casa-a-venda-com-2-quartos-no-bela-vista-palhoca-8717322.html
A38: venda_casa | B38: Casa | C38: 2 | D38: 0 | E38: 470000 | G38: Crédito Real Biguaçu | H38: https://www.imoveis-sc.com.br/palhoca/comprar/casa/bela-vista/casa-a-venda-com-2-quartos-no-bela-vista-palhoca-8656157.html
A39: venda_casa | B39: Casa | C39: 2 | D39: 0 | E39: 500000 | G39: Crédito Real Grande Floripa | H39: https://www.imoveis-sc.com.br/palhoca/comprar/casa/bela-vista/casa-a-venda-com-2-quartos-no-bela-vista-palhoca-8716062.html
A40: venda_casa | B40: Casa | C40: 3 | D40: 0 | E40: 580000 | G40: Crédito Real Biguaçu | H40: https://www.imoveis-sc.com.br/palhoca/comprar/casa/bela-vista/casa-a-venda-com-3-quartos-no-bela-vista-palhoca-8656412.html
A41: venda_casa | B41: Casa | C41: 2 | D41: 0 | E41: 550000 | G41: Crédito Real Village | H41: https://www.imoveis-sc.com.br/palhoca/comprar/casa/bela-vista/casa-a-venda-com-2-quartos-no-bela-vista-palhoca-8718702.html
...

Sheet Saíram da lista
A1: Lotes que deixaram o portal
A2: Histórico acumulado. O portal não declara a causa da saída — pode ser arremate, suspensão ou retirada. Serve para calibrar lance futuro: em que faixa de preço e depois de qual data de certame os lotes somem. Só entra aqui o lote ausente em duas rodadas consecutivas. 13 registro(s).
A4: data_saida | B4: id | C4: cidade | D4: bairro | E4: endereco | F4: tipo | G4: area_privativa | H4: valor_avaliacao | I4: ultimo_preco | J4: modalidade | K4: situacao | L4: datas_certame | M4: edital | N4: observacao
A5: 03/10/2026 | B5: 160000012143-0 | C5: FLORIANOPOLIS | D5: JOAO PAULO | E5: RUA VERGILIO PONCIANO,N. 133 LT 15, JOAO PAULO - CEP: 88030-680, FLORIANOPOLIS - SANTA CATARINA | F5: Casa | G5: 274,96m2 | H5: 3.120.000,00 | I5: 1.872.000,00 | J5: Leilão SFI | K5: Ocupado | L5: 05/10/2026 / 09/10/2026 | M5: 0046/0226 - CPA/RE | N5: saiu da lista do portal; causa nao declarada pela fonte
A6: 03/10/2026 | B6: 844440736266-6 | C6: SAO_JOSE | D6: SERRARIA | E6: RUA WENCESLAU EVARISTO SILVA,N. 31 APTO. 105 BL EMILIA, SERRARIA - CEP: 88115-200, SAO JOSE - SANTA CATARINA | F6: Apartamento | G6: 46,52m2 | H6: 240.000,00 | I6: 144.000,00 | J6: Leilão SFI | K6: Ocupado | L6: 28/09/2026 / 02/10/2026 | M6: 0044/0226 - CPA/RE | N6: saiu da lista do portal; causa nao declarada pela fonte
A7: 03/10/2026 | B7: 000001018127-9 | C7: SAO_JOSE | D7: KOBRASOL | E7: AVENIDA LEDIO JOAO MARTINS,N. 554 SL 106 ED DOM ALEXANDRE, KOBRASOL - CEP: 88101-100, SAO JOSE - SANTA CATARINA | F7: Sala | G7: 33,30m2 | H7: 250.000,00 | I7: 395.960,11 | J7: Leilão SFI | K7: Ocupado | L7: 28/09/2026 / 02/10/2026 | M7: 0044/0226 - CPA/RE | N7: saiu da lista do portal; causa nao declarada pela fonte
A8: 03/10/2026 | B8: 878771586575-0 | C8: PALHOCA | D8: LOT PQ VALE VERDE | E8: AVENIDA PAULO ROBERTO VIDAL,N. 2050 APTO. 102 1 PAV BL 12 LT 1 A 18 QD B1 VG 233, LOT PQ VALE VERDE - CEP: 88132-599, PALHOCA - SANTA CATARINA | F8: Apartamento | G8: 43,80m2 | H8: 223.000,00 | I8: 133.800,00 | J8: Leilão SFI | K8: Ocupado | L8: 28/09/2026 / 02/10/2026 | M8: 0044/0226 - CPA/RE | N8: saiu da lista do portal; causa nao declarada pela fonte
A9: 03/10/2026 | B9: 144441764402-0 | C9: PALHOCA | D9: CENTRO | E9: RUA EMELINE MATILDES CRISEMANN SCHEIDT,N. 257 APTO. 704 9 PAV, 13, CENTRO - CEP: 88130-290, PALHOCA - SANTA CATARINA | F9: Apartamento | G9: 72,45m2 | H9: 580.000,00 | I9: 477.998,55 | J9: Leilão SFI | K9: Ocupado | L9: 28/09/2026 / 02/10/2026 | M9: 0044/0226 - CPA/RE | N9: saiu da lista do portal; causa nao declarada pela fonte
A10: 02/10/2026 | B10: 000001028634-4 | C10: FLORIANOPOLIS | D10: ESTREITO | E10: AVENIDA GOVERNADOR IVO SILVEIRA,N. 2487, ESTREITO - CEP: 88085-001, FLORIANOPOLIS - SANTA CATARINA | F10: Comercial | G10: 577,10m2 | H10: 3.035.000,00 | I10: 1.934.248,90 | J10: Venda Online | K10: Ocupado | N10: RETRATADO: reapareceu na lista em 03/10/2026 — a ausencia de 02/10 era indisponibilidade da fonte, nao saida. Nao contar como saida.
A11: 30/09/2026 | B11: 844442822457-2 | C11: SAO_JOSE | D11: REAL PARQUE | E11: RUA ALMERINDA FRANCISCO DOS SANTOS,N. 19 APTO. 32 BL 5 VG 02 DEPÓSITO 02, REAL PARQUE - CEP: 88113-487, SAO JOSE - SANTA CATARINA | F11: Apartamento | G11: 57,22m2 | H11: 256.500,00 | I11: 157.056,10 | J11: Licitação Aberta | K11: Ocupado | L11: 29/09/2026 | M11: 0031/0326 - CPVE/RE | N11: saiu da lista do portal; causa nao declarada pela fonte
A12: 29/09/2026 | B12: 878770360836-7 | C12: PALHOCA | D12: BELA VISTA | E12: RUA SEBASTIAO ALZEMIRO DOS SANTOS,N. 347 APTO. 104 BL 11, BELA VISTA - CEP: 88137-640, PALHOCA - SANTA CATARINA | F12: Apartamento | G12: 45,61m2 | H12: 240.000,00 | I12: 144.000,00 | J12: Leilão SFI | K12: Ocupado | L12: 08/10/2026 / 15/10/2026 | M12: 0047/0226 - CPA/RE | N12: saiu da lista do portal; causa nao declarada pela fonte
A13: 25/09/2026 | B13: 878771288948-9 | C13: SAO_JOSE | D13: FORQUILHAS LESTE | E13: RUA VIDAL VICENTE ANDRADE,N. 1171 APTO. 104 BLOCO 04 VAGA 189, FORQUILHAS LESTE - CEP: 88107-001, SAO JOSE - SANTA CATARINA | F13: Apartamento | G13: 40,28m2 | H13: 260.000,00 | I13: 156.000,00 | J13: Leilão SFI | K13: Ocupado | L13: 18/09/2026 / 24/09/2026 | M13: 0043/0226 - CPA/RE | N13: saiu da lista do portal; causa nao declarada pela fonte
A14: 25/09/2026 | B14: 855553476258-4 | C14: SAO_JOSE | D14: REAL PARQUE | E14: RUA ALMERINDA FRANCISCO DOS SANTOS,N. 176 APTO. 405 BLOCO B, REAL PARQUE - CEP: 88113-487, SAO JOSE - SANTA CATARINA | F14: Apartamento | G14: 60,28m2 | H14: 296.000,00 | I14: 177.600,00 | J14: Leilão SFI | K14: Ocupado | L14: 18/09/2026 / 24/09/2026 | M14: 0043/0226 - CPA/RE | N14: saiu da lista do portal; causa nao declarada pela fonte
A15: 25/09/2026 | B15: 144442332474-0 | C15: SAO_JOSE | D15: POTECAS | E15: RUA HELMUTH FETT,N. 254 CASA 03, POTECAS - CEP: 88119-368, SAO JOSE - SANTA CATARINA | F15: Casa | G15: 71,43m2 | H15: 360.000,00 | I15: 337.393,03 | J15: Leilão SFI | K15: Ocupado | L15: 18/09/2026 / 24/09/2026 | M15: 0043/0226 - CPA/RE | N15: saiu da lista do portal; causa nao declarada pela fonte
A16: 19/09/2026 | B16: 878771560417-5 | C16: SAO_JOSE | D16: SERTAO DO MARUIM | E16: RUA CELSO JOSE KUERTEN,N. 18 APTO. 103 BL 02 TERREO, SERTAO DO MARUIM - CEP: 88122-135, SAO JOSE - SANTA CATARINA | F16: Apartamento | G16: 45,89m2 | H16: 230.000,00 | I16: 152.002,30 | J16: Leilão SFI | K16: Ocupado | L16: 14/09/2026 / 18/09/2026 | M16: 0042/0226 - CPA/RE | N16: saiu da lista do portal; causa nao declarada pela fonte
A17: 19/09/2026 | B17: 855551517677-2 | C17: SAO_JOSE | D17: ROCADO | E17: RUA R ATAULFO ALVES,N. 85 APTO. 102 TIPO D - 1º PAVIMENTO, VG 21, ROCADO - CEP: 88108-220, SAO JOSE - SANTA CATARINA | F17: Apartamento | G17: 62,93m2 | H17: 465.000,00 | I17: 279.000,00 | J17: Leilão SFI | K17: Ocupado | L17: 14/09/2026 / 18/09/2026 | M17: 0042/0226 - CPA/RE | N17: saiu da lista do portal; causa nao declarada pela fonte
